from django.core.exceptions import ValidationError


def company_user_validation(company):
    pass


