from django.core.exceptions import ValidationError
from django.contrib.auth.decorators import user_passes_test
from django.contrib.auth.models import Group


def company_user_validation(request):
    pass





